<?xml version="1.0" encoding="utf-8"?>

<robot
  name="auto_bot">
  <link
    name="base_link">
    <inertial>
      <origin
        xyz="-0.0036199 -0.00018682 0.020509"
        rpy="0 0 0" />
      <mass
        value="0.68398" />
      <inertia
        ixx="0.0011884"
        ixy="-2.7245E-07"
        ixz="-5.8366E-07"
        iyy="0.0019329"
        iyz="-2.8598E-08"
        izz="0.0030848" />
    </inertial>
    <visual>
      <origin
        xyz="0 0 0"
        rpy="0 0 0" />
      <geometry>
        <mesh
          filename="package://src/my_bot/meshes/base_link.STL" />
      </geometry>
      <material
        name="">
        <color
          rgba="0.79216 0.81961 0.93333 1" />
      </material>
    </visual>
    <collision>
      <origin
        xyz="0 0 0"
        rpy="0 0 0" />
      <geometry>
        <mesh
          filename="package://src/my_bot/meshes/base_link.STL" />
      </geometry>
    </collision>
  </link>
  <link
    name="left_wheel">
    <inertial>
      <origin
        xyz="-7.30946124161136E-06 6.05926290753178E-07 -0.00735557634822882"
        rpy="0 0 0" />
      <mass
        value="0.166401766026555" />
      <inertia
        ixx="6.72512467207035E-05"
        ixy="1.08698662482317E-10"
        ixz="-7.21226323098898E-09"
        iyy="6.72526655919658E-05"
        iyz="5.76200802381028E-10"
        izz="0.000113203111878345" />
    </inertial>
    <visual>
      <origin
        xyz="0 0 0"
        rpy="0 0 0" />
      <geometry>
        <mesh
          filename="package://src/my_bot/meshes/left_wheel.STL" />
      </geometry>
      <material
        name="">
        <color
          rgba="0.792156862745098 0.819607843137255 0.933333333333333 1" />
      </material>
    </visual>
    <collision>
      <origin
        xyz="0 0 0"
        rpy="0 0 0" />
      <geometry>
        <mesh
          filename="package://src/my_bot/meshes/left_wheel.STL" />
      </geometry>
    </collision>
  </link>
  <joint
    name="left_wheel_joint"
    type="continuous">
    <origin
      xyz="-0.072399 0.122 -0.035"
      rpy="-1.5708 0 0" />
    <parent
      link="base_link" />
    <child
      link="left_wheel" />
    <axis
      xyz="0 0 -1" />
    <limit
      effort="10"
      velocity="10" />
    <dynamics
      damping="0.1"
      friction="0.1" />
  </joint>
  <link
    name="right_wheel">
    <inertial>
      <origin
        xyz="-6.00047820940516E-06 -4.2177756637285E-06 0.00735557634822942"
        rpy="0 0 0" />
      <mass
        value="0.166401766026527" />
      <inertia
        ixx="6.72517041125309E-05"
        ixy="-6.72003155473924E-10"
        ixz="5.93163983577509E-09"
        iyy="6.72522082001198E-05"
        iyz="4.14299374399831E-09"
        izz="0.000113203111878325" />
    </inertial>
    <visual>
      <origin
        xyz="0 0 0"
        rpy="0 0 0" />
      <geometry>
        <mesh
          filename="package://src/my_bot/meshes/right_wheel.STL" />
      </geometry>
      <material
        name="">
        <color
          rgba="0.792156862745098 0.819607843137255 0.933333333333333 1" />
      </material>
    </visual>
    <collision>
      <origin
        xyz="0 0 0"
        rpy="0 0 0" />
      <geometry>
        <mesh
          filename="package://src/my_bot/meshes/right_wheel.STL" />
      </geometry>
    </collision>
  </link>
  <joint
    name="right_wheel_joint"
    type="continuous">
    <origin
      xyz="-0.072199 -0.122 -0.035"
      rpy="-1.5708 0 0" />
    <parent
      link="base_link" />
    <child
      link="right_wheel" />
    <axis
      xyz="0 0 1" />
    <limit
      effort="10"
      velocity="10" />
    <dynamics
      damping="0.1"
      friction="0.1" />
  </joint>
  <link
    name="castor">
    <inertial>
      <origin
        xyz="0.00358577396418788 -0.000177887240872643 -0.00911410419533031"
        rpy="0 0 0" />
      <mass
        value="0.00488347250929968" />
      <inertia
        ixx="4.96311798297696E-07"
        ixy="1.24312765635125E-08"
        ixz="1.47708407077018E-07"
        iyy="5.8000968127077E-07"
        iyz="-1.4715247801523E-08"
        izz="6.7142121232199E-07" />
    </inertial>
    <visual>
      <origin
        xyz="0 0 0"
        rpy="0 0 0" />
      <geometry>
        <mesh
          filename="package://src/my_bot/meshes/castor.STL" />
      </geometry>
      <material
        name="">
        <color
          rgba="0.792156862745098 0.819607843137255 0.933333333333333 1" />
      </material>
    </visual>
    <collision>
      <origin
        xyz="0 0 0"
        rpy="0 0 0" />
      <geometry>
        <mesh
          filename="package://src/my_bot/meshes/castor.STL" />
      </geometry>
    </collision>
  </link>
  <joint
    name="castor_joint"
    type="continuous">
    <origin
      xyz="0.10065 -0.00013159 -0.006"
      rpy="0 0 0" />
    <parent
      link="base_link" />
    <child
      link="castor" />
    <axis
      xyz="0 0 1" />
    <limit
      effort="10"
      velocity="10" />
  </joint>
  <link
    name="castor_wheel">
    <inertial>
      <origin
        xyz="0 -1.38777878078145E-17 0"
        rpy="0 0 0" />
      <mass
        value="0.00580116776092969" />
      <inertia
        ixx="4.34736665680399E-07"
        ixy="-2.02766846973742E-27"
        ixz="3.12471930694403E-13"
        iyy="4.34736665680072E-07"
        iyz="-1.93857181522841E-21"
        izz="7.33478440777628E-07" />
    </inertial>
    <visual>
      <origin
        xyz="0 0 0"
        rpy="0 0 0" />
      <geometry>
        <mesh
          filename="package://src/my_bot/meshes/castor_wheel.STL" />
      </geometry>
      <material
        name="">
        <color
          rgba="0.792156862745098 0.819607843137255 0.933333333333333 1" />
      </material>
    </visual>
    <collision>
      <origin
        xyz="0 0 0"
        rpy="0 0 0" />
      <geometry>
        <mesh
          filename="package://src/my_bot/meshes/castor_wheel.STL" />
      </geometry>
    </collision>
  </link>
  <joint
    name="castor_wheel_joint"
    type="continuous">
    <origin
      xyz="0.019452 0 -0.0298"
      rpy="-1.5708 0 0" />
    <parent
      link="castor" />
    <child
      link="castor_wheel" />
    <axis
      xyz="0 0 -1" />
    <limit
      effort="10"
      velocity="10" />
    <dynamics
      damping="0.1"
      friction="0.1" />
  </joint>
</robot>